<?xml version="1.0" ?>
<robot name="mybot" xmlns:xacro="https://www.ros.org/wiki/xacro" >
<material name="black">
 <color rgba="0.0 0.0 0.0 1.0"/>
 </material>
 <material name="blue">
 <color rgba="0.203125 0.23828125 0.28515625 1.0"/>
 </material>
 <material name="green">
 <color rgba="0.0 0.8 0.0 1.0"/>
 </material>
 <material name="grey">
 <color rgba="0.2 0.2 0.2 1.0"/>
 </material>
 <material name="orange">
 <color rgba="1.0 0.423529411765 0.0392156862745 1.0"/>
 </material>
 <material name="brown">
 <color rgba="0.870588235294 0.811764705882 0.764705882353 1.0"/>
 </material>
 <material name="red">
 <color rgba="0.80078125 0.12890625 0.1328125 1.0"/>
 </material>
 <material name="white">
 <color rgba="1.0 1.0 1.0 1.0"/>
 </material>

 <gazebo reference="link_chassis">
 <material>Gazebo/Orange</material>
 </gazebo>
 <gazebo reference="link_left_wheel">
 <material>Gazebo/Blue</material>
 </gazebo>
 <gazebo reference="link_right_wheel">
 <material>Gazebo/Blue</material>
 </gazebo>

 <gazebo>
 <plugin filename="libgazebo_ros_diff_drive.so" name="differential_drive_controller">
 <alwaysOn>true</alwaysOn>
 <updateRate>20</updateRate>
 <leftJoint>joint_left_wheel</leftJoint>
 <rightJoint>joint_right_wheel</rightJoint>
 <wheelSeparation>0.4</wheelSeparation>
 <wheelDiameter>0.2</wheelDiameter>
 <torque>0.1</torque>
 <commandTopic>cmd_vel</commandTopic>
 <odometryTopic>odom</odometryTopic>
 <odometryFrame>odom</odometryFrame>
 <robotBaseFrame>link_chassis</robotBaseFrame>
 </plugin>
 </gazebo>

<!-- IMU Sensor -->
  <gazebo reference="imu_link">
    <gravity>true</gravity>
    <sensor name="imu_sensor" type="imu">
      <always_on>true</always_on>
      <update_rate>100</update_rate>
      <visualize>true</visualize>
      <topic>__default_topic__</topic>
      <plugin filename="libgazebo_ros_imu_sensor.so" name="imu_plugin">
        <topicName>imu</topicName>
        <bodyName>imu_link</bodyName>
        <updateRateHZ>10.0</updateRateHZ>
        <gaussianNoise>0.0</gaussianNoise>
        <xyzOffset>0 0 0</xyzOffset>
        <rpyOffset>0 0 0</rpyOffset>
        <frameName>imu_link</frameName>
        <initialOrientationAsReference>false</initialOrientationAsReference>
      </plugin>
      <pose>0 0 0 0 0 0</pose>
    </sensor>
  </gazebo>

  <!-- GPS Sensor -->
  <gazebo>
    <plugin name="novatel_gps_sim" filename="libhector_gazebo_ros_gps.so">
      <alwaysOn>1</alwaysOn>
      <updateRate>10.0</updateRate>
      <bodyName>base_footprint</bodyName>
      <topicName>fix</topicName>
      <velocityTopicName>fix_velocity</velocityTopicName>
      <drift>5.0 5.0 5.0</drift>
      <gaussianNoise>0.1 0.1 0.1</gaussianNoise>
      <velocityDrift>0 0 0</velocityDrift>
      <velocityGaussianNoise>0.1 0.1 0.1</velocityGaussianNoise>
    </plugin>
  </gazebo>

<link name="link_chassis">
 <!-- pose and inertial -->
 <pose>0 0 0.1 0 0 0</pose>
 <inertial>
 <mass value="5"/>
 <origin rpy="0 0 0" xyz="0 0 0.1"/>
 <inertia ixx="0.0395416666667" ixy="0" ixz="0" iyy="0.106208333333" iyz="0"
izz="0.106208333333"/>
 </inertial>
 <!---Body-->
 <collision name="collision_chassis">
 <geometry>
 <box size="0.5 0.3 0.07"/>
 </geometry>
 </collision>
 <visual>
 <origin rpy="0 0 0" xyz="0 0 0"/>
 <geometry>
 <box size="0.5 0.3 0.07"/>
 </geometry>
 <material name="blue"/>
 </visual>
 <!-- caster front -->
 <collision name="caster_front_collision">
 <origin rpy=" 0 0 0" xyz="0.35 0 -0.05"/>
 <geometry>
 <sphere radius="0.05"/>
 </geometry>
 <surface>
 <friction>
 <ode>
 <mu>0</mu>
 <mu2>0</mu2>
 <slip1>1.0</slip1>
 <slip2>1.0</slip2>
 </ode>
 </friction>
 </surface>
 </collision>
 <visual name="caster_front_visual">
 <origin rpy=" 0 0 0" xyz="0.2 0 -0.05"/>
 <geometry>
 <sphere radius="0.05"/>
 </geometry>
 </visual>
 </link>
 <!-- Create wheel right -->

 <link name="link_right_wheel">
 <inertial>
 <mass value="0.2"/>
 <origin rpy="0 1.5707 1.5707" xyz="0 0 0"/>
 <inertia ixx="0.00052666666" ixy="0" ixz="0" iyy="0.00052666666" iyz="0" izz="0.001"/>
 </inertial>

 <collision name="link_right_wheel_collision">
 <origin rpy="0 1.5707 1.5707" xyz="0 0 0" />
 <geometry>
 <cylinder length="0.04" radius="0.1"/>
 </geometry>
 </collision>

 <visual name="link_right_wheel_visual">
 <origin rpy="0 1.5707 1.5707" xyz="0 0 0"/>
 <geometry>
 <cylinder length="0.04" radius="0.1"/>
 </geometry>
 </visual>

</link>
 <!-- Joint for right wheel -->
 <joint name="joint_right_wheel" type="continuous">
 <origin rpy="0 0 0" xyz="-0.05 0.15 0"/>
 <child link="link_right_wheel" />
 <parent link="link_chassis"/>
 <axis rpy="0 0 0" xyz="0 1 0"/>
 <limit effort="10000" velocity="1000"/>
 <joint_properties damping="1.0" friction="1.0" />
 </joint>

<!-- Left Wheel link -->

<link name="link_left_wheel">
 <inertial>
 <mass value="0.2"/>
 <origin rpy="0 1.5707 1.5707" xyz="0 0 0"/>
 <inertia ixx="0.00052666666" ixy="0" ixz="0" iyy="0.00052666666" iyz="0" izz="0.001"/>
 </inertial>

 <collision name="link_left_wheel_collision">
 <origin rpy="0 1.5707 1.5707" xyz="0 0 0" />
 <geometry>
 <cylinder length="0.04" radius="0.1"/>
 </geometry>
 </collision>

 <visual name="link_left_wheel_visual">
 <origin rpy="0 1.5707 1.5707" xyz="0 0 0"/>
 <geometry>
 <cylinder length="0.04" radius="0.1"/>
 </geometry>
 </visual>

 </link>
<!-- Joint for left wheel -->
 <joint name="joint_left_wheel" type="continuous">
 <origin rpy="0 0 0" xyz="-0.05 -0.15 0"/>
 <child link="link_left_wheel" />
 <parent link="link_chassis"/>
 <axis rpy="0 0 0" xyz="0 1 0"/>
 <limit effort="10000" velocity="1000"/>
 <joint_properties damping="1.0" friction="1.0" />
 </joint>
</robot>